<?xml version="1.0" encoding="utf-8"?>
<robot name="wheelchair" xmlns:xacro="http://www.ros.org/wiki/xacro">
	<xacro:include filename="$(find wheelchair_description)/urdf/wheelchair_0.0.gazebo" />
	<xacro:property name = "lower" value = "-1000"/>
	<xacro:property name = "upper" value = "1000"/>
  	<link name="base_footprint"/>

  	<link name='base_link'>
	    <visual>
	    	<origin rpy= "0 -0 0" xyz = "0 0 0"/>
		    <geometry>
		    	<mesh scale=" 1 1 1" filename = "package://wheelchair_description/meshes/Wheelchair-base_col.STL"/>
		    </geometry>
	    </visual>
	    <collision>
        	<origin rpy= "0 -0 0" xyz = "0 0 0"/>
        	<geometry>
          		<mesh scale=" 1 1 1" filename = "package://wheelchair_description/meshes/Wheelchair-base_col.STL"/>
        	</geometry>
      	</collision>
	    <inertial>
			<origin rpy= "0 -0 0" xyz = "0.13 0 0.5"/>
	    	<mass value="63.4"/>
	     	<inertia ixx="3.853724" ixy="7e-06" ixz="0.022948" iyy="3.218409" iyz="7e-06" izz="5.02"/>
 	    </inertial>
  	</link>
  
  	<link name="Left-Caster-Wheel">
	  	<visual>
	  		<origin rpy = "0 -0 0" xyz = "-0.32661 -0.24669 -0.06"/>
	  		<geometry>
	  			<mesh scale=" 1 1 1" filename = "package://wheelchair_description/meshes/Left-Caster-Wheel.STL"/>
	  		</geometry>
	  	</visual>
	  	<collision>
        	<origin rpy = "0 -0 0" xyz = "-0.32661 -0.24669 -0.06"/>
        		<geometry>
          			<mesh scale=" 1 1 1" filename = "package://wheelchair_description/meshes/Left-Caster-Wheel_col.STL"/>
        		</geometry>
     	</collision>
	  	<inertial>
        	<mass value="0.149507"/>
         	<inertia ixx="0.000176" ixy="8e-06" ixz="0.0" iyy="0.000339" iyz="0.0" izz="0.000176"/>
 	    </inertial>
  	</link>

  	<link name="Left-Caster-Yaw">
	  	<visual>
		  	<origin rpy = "0 -0 0"  xyz = "-0.35956 -0.24291 -0.1517"/>
		  	<geometry>
		  		<mesh scale=" 1 1 1" filename = "package://wheelchair_description/meshes/Left-Caster-Yaw.STL"/>
		  	</geometry>
		</visual>
		<collision>
          	<origin rpy = "0 -0 0" xyz = "-0.35956 -0.24291 -0.1517"/>
          	<geometry>
            	<mesh scale=" 1 1 1" filename = "package://wheelchair_description/meshes/Left-Caster-Yaw_col.STL"/>
          	</geometry>
      	</collision>
		<inertial>
        	<mass value="0.279085"/>
         	<inertia ixx="0.000442" ixy="1e-06" ixz="0.000123" iyy="0.000458" iyz="8e-06" izz="0.000182"/>
 	    </inertial>
 	</link>

  	<link name="Left-Wheel">
	  	<visual>
	  		<origin rpy  = "0 -0 0" xyz = "-0 -0.26808 -0.305"/>
	  		<geometry>
		  		<mesh scale=" 1 1 1" filename = "package://wheelchair_description/meshes/Left-Wheel.STL"/>
		  	</geometry>
	  	</visual>
	  	<collision>
        	<origin rpy  = "0 -0 0" xyz = "-0 -0.26808 -0.305"/>
        	<geometry>
          		<mesh scale=" 1 1 1" filename = "package://wheelchair_description/meshes/Left-Wheel_col.STL"/>
        	</geometry>
      	</collision>
	  	<inertial>
        	<mass value="4.08233"/>
         	<inertia ixx="0.112302" ixy="0" ixz="0" iyy="0.222779" iyz="0" izz="0.112302"/>
 	    </inertial>
  	</link>

  	<link name="Right-Caster-Wheel">
	  	<visual>
	  		<origin rpy = "0 -0 0" xyz = "-0.32661 0.24669 -0.06"/>
	  		<geometry>
	  			<mesh scale=" 1 1 1" filename = "package://wheelchair_description/meshes/Right-Caster-Wheel.STL"/>
	  		</geometry>
	  	</visual>
	  	<collision>
        	<origin rpy  = "0 -0 0" xyz = "-0.32661 0.24669 -0.06"/>
        	<geometry>
          		<mesh scale=" 1 1 1" filename = "package://wheelchair_description/meshes/Right-Caster-Wheel_col.STL"/>
        	</geometry>
      	</collision>
	  	<inertial>
        	<mass value="0.149507"/>
         	<inertia ixx="0.000176" ixy="8e-06" ixz="0.0" iyy="0.000339" iyz="0.0" izz="0.000176"/>
 	    </inertial>
  	</link>

  	<link name="Right-Caster-Yaw">
	  	<visual>
		  	<origin rpy = "0 -0 0" xyz = "-0.35956 0.24291 -0.1517"/>
		  	<geometry>
		  		<mesh scale=" 1 1 1" filename = "package://wheelchair_description/meshes/Right-Caster-Yaw.STL"/>
		  	</geometry>
		</visual>
		<collision>
        	<origin rpy = "0 -0 0" xyz = "-0.35956 0.24291 -0.1517"/>
        	<geometry>
          		<mesh scale=" 1 1 1" filename = "package://wheelchair_description/meshes/Right-Caster-Yaw_col.STL"/>
        	</geometry>
     	</collision>
		<inertial>
	        <mass value="0.279085"/>
	         <inertia ixx="0.000442" ixy="1e-06" ixz="0.000123" iyy="0.000458" iyz="8e-06" izz="0.000182"/>
 	    </inertial>
  	</link>

  	<link name="Right-Wheel">
	  	<visual>
	  		<origin rpy  = "0.0 0.0 0.0" xyz = "0.0 0.26808 -0.305"/>
	  		<geometry>
		  		<mesh scale=" 1 1 1" filename = "package://wheelchair_description/meshes/Right-Wheel.STL"/>
		  	</geometry>
	  	</visual>
	  	<collision>
        	<origin rpy  = "0.0 0.0 0.0" xyz = "0.0 0.26808 -0.305"/>
        	<geometry>
          		<mesh scale=" 1 1 1" filename = "package://wheelchair_description/meshes/Right-Wheel_col.STL"/>
        	</geometry>
      	</collision>
	  	<inertial>
	        <mass value="4.08233"/>
         	<inertia ixx="0.112302" ixy="0" ixz="0" iyy="0.222779" iyz="0" izz="0.112302"/>
 	    </inertial>
  	</link>

	<joint name="base_joint" type="fixed">
	    <parent link="base_footprint"/>
	    <child link="base_link"/>
	    <origin xyz="0.0 0.0 0.0" rpy="0 0 0"/>
  	</joint>

	<joint name="Wheelchair-base-Left-Caster-Yaw" type="continuous">
	   <parent link="base_link"/>
	   <child link="Left-Caster-Yaw"/>
	   <origin xyz="0.35956 0.24291 0.1517"/>
	   <axis xyz="0 0 -1"/>
	   <limit effort= "1000" velocity = "10"/>
	   <dynamics damping = "0.0" friction ="1.0"/>
	</joint>

	<joint name="Wheelchair-base-Right-Caster-Yaw" type="continuous">
	   <parent link="base_link"/>
	   <child link="Right-Caster-Yaw"/>
	   <origin xyz="0.35956 -0.24291 0.1517"/>
	   <axis xyz="0 0 1"/>
	   <limit effort= "1000" velocity = "10"/>
	   <dynamics damping = "0.0" friction ="1.0"/>
	</joint>

	<joint name="WheelL_cont" type="continuous">
	   <parent link="base_link"/>
	   <child link="Left-Wheel"/>
	   <origin xyz="0.0 0.26808 0.305"/>
	   <axis xyz="0 1 0"/>
	   <limit effort= "1000" velocity = "10"/>
	   <dynamics damping = "0.0" friction ="0.00263"/>
	</joint>

	<joint name="WheelR_cont" type="continuous">
	   <parent link="base_link"/>
	   <child link="Right-Wheel"/>
	   <origin xyz="0 -0.26808 0.305"/>
	   <axis xyz="0 1 0"/>
	   <limit effort= "1000"  velocity = "10"/>
	   <dynamics damping = "0.0" friction ="0.00263"/>
	</joint>

	<joint name="Left-Caster-Yaw-Left-Caster-Wheel" type="continuous">
	   <parent link="Left-Caster-Yaw"/>
	   <child link="Left-Caster-Wheel"/>
	   <origin xyz="-0.03295 -0.00183 -0.0917"/>
	   <axis xyz="0 1 0"/>
	   <limit effort= "1000" velocity = "10"/>
	   <dynamics damping = ".0" friction ="0.000918"/>
	</joint>

	<joint name="Right-Caster-Yaw-Right-Caster-Wheel" type="continuous">
	   <parent link="Right-Caster-Yaw"/>
	   <child link="Right-Caster-Wheel"/>
	   <origin xyz="-0.03295 0.00183 -0.0917"/>
	   <axis xyz="0 1 0"/>
	   <limit effort= "1000" velocity = "10"/>
	   <dynamics damping = ".0" friction ="0.000918"/>
	</joint>
	
    <transmission name="Wheelchair_base_Left_Wheel-trans">
      	<type>transmission_interface/SimpleTransmission</type>
      	<actuator name="Wheelchair_base_Left_Wheel-motor">
      		<hardwareInterface>hardware_interface/EffortJointInterface</hardwareInterface>
        	<mechanicalReduction>1</mechanicalReduction>
     	</actuator>
      	<joint name="WheelL_cont">
        	<!-- <hardwareInterface>hardware_interface/VelocityJointInterface</hardwareInterface> -->
        	<hardwareInterface>hardware_interface/EffortJointInterface</hardwareInterface>
      	</joint>
    </transmission> 

    <transmission name="Wheelchair_base_Right_Wheel-trans">
      	<type>transmission_interface/SimpleTransmission</type>
      	<actuator name="Wheelchair_base_Right_Wheel-motor">
      		<hardwareInterface>hardware_interface/EffortJointInterface</hardwareInterface>
        	<mechanicalReduction>1</mechanicalReduction>
      	</actuator>
      	<joint name="WheelR_cont">
        	<!-- <hardwareInterface>hardware_interface/VelocityJointInterface</hardwareInterface> -->
        	<hardwareInterface>hardware_interface/EffortJointInterface</hardwareInterface>
      	</joint>
    </transmission>

</robot>