<?xml version="1.0" encoding="utf-8"?>
<!-- This URDF was automatically created by SolidWorks to URDF Exporter! Originally created by Stephen Brawner (brawner@gmail.com) 
     Commit Version: 1.5.1-0-g916b5db  Build Version: 1.5.7152.31018
     For more information, please see http://wiki.ros.org/sw_urdf_exporter -->
<robot name="Wheelchair_test">

  <!-- Import all Gazebo-customization elements, including Gazebo colors -->
  <!-- <xacro:include filename="$(find wheelchair_description)/urdf/wheelchair.gazebo" /> -->
  
  <!--extra dummy link -->

  <link name="base_footprint"/>

  <joint name="base_joint" type="fixed">
    <parent link="base_footprint"/>
    <child link="base_link"/>
    <origin xyz="0.0 0.0 0.0" rpy="0 0 0"/>
  </joint>

  <link name="base_link">
    <inertial>
      <origin
        xyz="-0.222515731055045 0.00824844167707826 0.220278773868655"
        rpy="0 0 0" />
      <mass
        value="25.5218455226117" />
      <inertia
        ixx="0.187867970908808"
        ixy="-1.16247288141221E-09"
        ixz="-0.0129329721363066"
        iyy="0.1870415689303"
        iyz="3.20069324721788E-09"
        izz="0.20373752352134" />
    </inertial>

    <visual>
      <origin
        xyz="0 0 0"
        rpy="0 0 0" />
      <geometry>
        <mesh
          filename="package://wheelchair_description/meshes/Frame.STL" />
      </geometry>
      <material
        name="">
        <color
          rgba="0.898039215686275 0.917647058823529 0.929411764705882 1" />
      </material>
    </visual>

    <collision>
      <origin
        xyz="0 0 0"
        rpy="0 0 0" />
      <geometry>
        <mesh
          filename="package://wheelchair_description/meshes/Frame.STL" />
      </geometry>
    </collision>
  </link>

  <gazebo reference="base_link">
    <turnGravityOff>false</turnGravityOff>
  </gazebo>

  <link name="Caster">
    <inertial>
      <origin
        xyz="-0.018675 -0.0023779 -0.066791"
        rpy="0 0 0" />
      <mass
        value="0.18692" />
      <inertia
        ixx="0.00031039"
        ixy="1.0543E-06"
        ixz="-0.00010185"
        iyy="0.00030225"
        iyz="-1.2968E-05"
        izz="0.00012277" />
    </inertial>

    <visual>
      <origin
        xyz="0 0 0"
        rpy="0 0 0" />
      <geometry>
        <mesh
          filename="package://wheelchair_description/meshes/Caster.STL" />
      </geometry>
      <material
        name="">
        <color
          rgba="0.89804 0.91765 0.92941 1" />
      </material>
    </visual>

    <collision>
      <origin
        xyz="0 0 0"
        rpy="0 0 0" />
      <geometry>
        <mesh
          filename="package://wheelchair_description/meshes/Caster.STL" />
      </geometry>
    </collision>
  </link>

  <gazebo reference="Caster">
    <material>Gazebo/Black</material>
    <turnGravityOff>false</turnGravityOff>
  </gazebo>

  <joint name="Caster_cont" type="continuous">
    <origin
      xyz="0.5078 0 0.00635"
      rpy="0 0 0" />
    <parent
      link="base_link" />
    <child
      link="Caster" />
    <axis
      xyz="0 0 1" />
    <limit
      effort="0"
      velocity="20" />
  </joint>

  <gazebo reference ="Caster_cont">
    <mu1 value="200.0"/>
    <mu2 value="100.0"/>
    <kp value="10000000.0"/>
    <kd value= "1.0"/>
</gazebo>

  <link name="WheelF">
    <inertial>
      <origin
        xyz="0 0 -2.7756E-17"
        rpy="0 0 0" />
      <mass
        value="2.1315" />
      <inertia
        ixx="0.0052886"
        ixy="-3.2526E-19"
        ixz="-1.09E-21"
        iyy="0.010349"
        iyz="-3.0141E-20"
        izz="0.0052886" />
    </inertial>

    <visual>
      <origin
        xyz="0 0 0"
        rpy="0 0 0" />
      <geometry>
        <mesh
          filename="package://wheelchair_description/meshes/WheelF.STL" />
      </geometry>
      <material
        name="">
        <color
          rgba="0.89804 0.91765 0.92941 1" />
      </material>
    </visual>

    <collision>
      <origin
        xyz="0 0 0"
        rpy="0 0 0" />
      <geometry>
        <mesh
          filename="package://wheelchair_description/meshes/WheelF.STL" />
      </geometry>
    </collision>
  </link>

  <gazebo reference="WheelF">
    <turnGravityOff>false</turnGravityOff>
  </gazebo>

  <joint name="WheelF_cont"  type="continuous">
    <origin
      xyz="-0.0518843000619276 -0.00660668610975347 -0.1478026"
      rpy="0 0 0.126653383400985" />
    <parent
      link="Caster" />
    <child
      link="WheelF" />
    <axis
      xyz="0 -1 0" />
    <limit
      effort="0"
      velocity="20" />
  </joint>

  <gazebo reference ="WheelF_cont">
    <mu1 value="200.0"/>
    <mu2 value="100.0"/>
    <kp value="10000000.0"/>
    <kd value= "1.0"/>
  </gazebo>

  <link name="SwingR">
    <inertial>
      <origin
        xyz="-0.14883 0.054597 -0.033745"
        rpy="0 0 0" />
      <mass
        value="4.8363" />
      <inertia
        ixx="0.0094524"
        ixy="-0.00067415"
        ixz="-0.0056619"
        iyy="0.022613"
        iyz="3.9175E-05"
        izz="0.018459" />
    </inertial>

    <visual>
      <origin
        xyz="0 0 0"
        rpy="0 0 0" />
      <geometry>
        <mesh
          filename="package://wheelchair_description/meshes/SwingR.STL" />
      </geometry>
      <material
        name="">
        <color
          rgba="0.75294 0.75294 0.75294 1" />
      </material>
    </visual>

    <collision>
      <origin
        xyz="0 0 0"
        rpy="0 0 0" />
      <geometry>
        <mesh
          filename="package://wheelchair_description/meshes/SwingR.STL" />
      </geometry>
    </collision>
  </link>

  <gazebo reference="SwingR">
    <turnGravityOff>false</turnGravityOff>
  </gazebo>

  <joint  name="SwingR_rev" type="revolute">
    <origin
      xyz="-0.106 -0.2118548 -0.0238887"
      rpy="0 0 0" />
    <parent
      link="base_link" />
    <child
      link="SwingR" />
    <axis
      xyz="0 1 0" />
    <limit
      lower="0"
      upper="0.67265"
      effort="0"
      velocity="2" />
    <dynamics damping="0.7" friction="0.0"/>
  </joint>

  <gazebo reference ="SwingR_rev">
    <mu1 value="200.0"/>
    <mu2 value="100.0"/>
    <kp value="10000000.0"/>
    <kd value= "1.0"/>
  </gazebo>

  <link name="WheelR">
    <inertial>
      <origin
        xyz="1.8579E-05 -0.0076777 -2.2937E-05"
        rpy="0 0 0" />
      <mass
        value="2.1893" />
      <inertia
        ixx="0.07871"
        ixy="3.2611E-07"
        ixz="-4.0455E-07"
        iyy="0.15702"
        iyz="-4.0261E-07"
        izz="0.07871" />
    </inertial>

    <visual>
      <origin
        xyz="0 0 0"
        rpy="0 0 0" />
      <geometry>
        <mesh
          filename="package://wheelchair_description/meshes/WheelR.STL" />
      </geometry>
      <material
        name="">
        <color
          rgba="0.75294 0.75294 0.75294 1" />
      </material>
    </visual>

    <collision>
      <origin
        xyz="0 0 0"
        rpy="0 0 0" />
      <geometry>
        <mesh
          filename="package://wheelchair_description/meshes/WheelR.STL" />
      </geometry>
    </collision>
  </link>

  <gazebo reference="WheelR">
    <turnGravityOff>false</turnGravityOff>
  </gazebo>

  <joint name="WheelR_cont" type="continuous">
    <origin
      xyz="-0.232195893808092 -0.0517862 -0.0361948462997351"
      rpy="0 0 0" />
    <parent
      link="SwingR" />
    <child
      link="WheelR" />
    <axis
      xyz="0 1 0" />
    <limit
      effort="0"
      velocity="16.25" />
  </joint>

  <gazebo reference ="WheelR_cont">
    <mu1 value="200.0"/>
    <mu2 value="100.0"/>
    <kp value="10000000.0"/>
    <kd value= "1.0"/>
  </gazebo>

  <link name="SwingL">
    <inertial>
      <origin
        xyz="-0.14883 -0.054597 -0.033745"
        rpy="0 0 0" />
      <mass
        value="4.8363" />
      <inertia
        ixx="0.0094524"
        ixy="0.00067415"
        ixz="-0.0056619"
        iyy="0.022613"
        iyz="-3.9175E-05"
        izz="0.018459" />
    </inertial>

    <visual>
      <origin
        xyz="0 0 0"
        rpy="0 0 0" />
      <geometry>
        <mesh
          filename="package://wheelchair_description/meshes/SwingL.STL" />
      </geometry>
      <material
        name="">
        <color
          rgba="0.75294 0.75294 0.75294 1" />
      </material>
    </visual>

    <collision>
      <origin
        xyz="0 0 0"
        rpy="0 0 0" />
      <geometry>
        <mesh
          filename="package://wheelchair_description/meshes/SwingL.STL" />
      </geometry>
    </collision>
  </link>

  <gazebo reference="SwingL">
    <turnGravityOff>false</turnGravityOff>
  </gazebo>

  <joint name="SwingL_rev" type="revolute">
    <origin
      xyz="-0.106 0.20947 -0.023889"
      rpy="0 0 0" />
    <parent
      link="base_link" />
    <child
      link="SwingL" />
    <axis
      xyz="0 1 0" />
    <limit
      lower="0"
      upper="0.67265"
      effort="0"
      velocity="2" />
    <dynamics damping="0.7" friction="0.0"/>
  </joint>

  <gazebo reference ="SwingL_rev">
    <mu1 value="200.0"/>
    <mu2 value="100.0"/>
    <kp value="10000000.0"/>
    <kd value= "1.0"/>
  </gazebo>

  <link name="WheelL">
    <inertial>
      <origin
        xyz="1.8579E-05 0.0076777 -2.2937E-05"
        rpy="0 0 0" />
      <mass
        value="2.1893" />
      <inertia
        ixx="0.07871"
        ixy="-3.2611E-07"
        ixz="-4.0455E-07"
        iyy="0.15702"
        iyz="4.0261E-07"
        izz="0.07871" />
    </inertial>

    <visual>
      <origin
        xyz="0 0 0"
        rpy="0 0 0" />
      <geometry>
        <mesh
          filename="package://wheelchair_description/meshes/WheelL.STL" />
      </geometry>
      <material
        name="">
        <color
          rgba="0.75294 0.75294 0.75294 1" />
      </material>
    </visual>

    <collision>
      <origin
        xyz="0 0 0"
        rpy="0 0 0" />
      <geometry>
        <mesh
          filename="package://wheelchair_description/meshes/WheelL.STL" />
      </geometry>
    </collision>
  </link>

  <gazebo reference="WheelL">
    <turnGravityOff>false</turnGravityOff>
  </gazebo>

  <joint name="WheelL_cont" type="continuous">
    <origin
      xyz="-0.2322 0.054167 -0.036195"
      rpy="0 0 0" />
    <parent
      link="SwingL" />
    <child
      link="WheelL" />
    <axis
      xyz="0 1 0" />
    <limit
      effort="0"
      velocity="16.25" />
  </joint>

  <gazebo reference ="WheelL_cont">
    <mu1 value="200.0"/>
    <mu2 value="100.0"/>
    <kp value="10000000.0"/>
    <kd value= "1.0"/>
  </gazebo>

  <!-- add transmission to swing arm joints -->
  <transmission name="SwingL_transmission">
    <type>transmission_interface/SimpleTransmission</type>
    <actuator name="SwingL_motor">
      <hardwareInterface>PositionJointInterface</hardwareInterface>
      <mechanicalReduction>1</mechanicalReduction>
    </actuator>
    <joint name="SwingL_rev">
      <hardwareInterface>hardware_interface/EffortJointInterface</hardwareInterface>
    </joint>
  </transmission>  

  <transmission name="SwingR_transmission">
    <type>transmission_interface/SimpleTransmission</type>
    <actuator name="SwingR_motor">
      <hardwareInterface>PositionJointInterface</hardwareInterface>
      <mechanicalReduction>1</mechanicalReduction>
    </actuator>
    <joint name="SwingR_rev">
      <hardwareInterface>hardware_interface/EffortJointInterface</hardwareInterface>
    </joint>
  </transmission> 
  <!-- add transmission to rear wheels -->
  <transmission name="WheelL_transmission">
    <type>transmission_interface/SimpleTransmission</type>
    <actuator name="WheelL_motor">
      <hardwareInterface>EffortJointInterface</hardwareInterface>
      <mechanicalReduction>1</mechanicalReduction>
    </actuator>
    <joint name="WheelL_cont">
      <hardwareInterface>hardware_interface/VelocityJointInterface</hardwareInterface>
    </joint>
  </transmission>  

  <transmission name="WheelR_transmission">
    <type>transmission_interface/SimpleTransmission</type>
    <actuator name="WheelR_motor">
      <hardwareInterface>EffortJointInterface</hardwareInterface>
      <mechanicalReduction>1</mechanicalReduction>
    </actuator>
    <joint name="WheelR_cont">
      <hardwareInterface>hardware_interface/VelocityJointInterface</hardwareInterface>
    </joint>
  </transmission> 

  <gazebo>
    <plugin name="gazebo_ros_control" filename= "libgazebo_ros_control.so">
     <robotNamespace>/</robotNamespace>
    </plugin>
  </gazebo>

  <gazebo>
    <plugin name="joint_state_publisher"
    filename="libgazebo_ros_joint_state_publisher.so">
    <jointName>Caster_cont, WheelF_cont</jointName>
    </plugin>
  </gazebo>
  
</robot>