<?xml version="1.0" encoding="utf-8"?>
<!-- This URDF was automatically created by SolidWorks to URDF Exporter! Originally created by Stephen Brawner (brawner@gmail.com) 
     Commit Version: 1.5.1-0-g916b5db  Build Version: 1.5.7152.31018
     For more information, please see http://wiki.ros.org/sw_urdf_exporter -->
<robot
  name="wheelchair">
  <link
    name="Frame">
    <inertial>
      <origin
        xyz="-0.222515731055045 0.00824844167707826 0.220278773868655"
        rpy="0 0 0" />
      <mass
        value="25.5218455226117" />
      <inertia
        ixx="0.187867970908808"
        ixy="-1.16247288141221E-09"
        ixz="-0.0129329721363066"
        iyy="0.1870415689303"
        iyz="3.20069324721788E-09"
        izz="0.20373752352134" />
    </inertial>
    <visual>
      <origin
        xyz="0 0 0"
        rpy="0 0 0" />
      <geometry>
        <mesh
          filename="package://wheelchair/meshes/Frame.STL" />
      </geometry>
      <material
        name="">
        <color
          rgba="0.898039215686275 0.917647058823529 0.929411764705882 1" />
      </material>
    </visual>
    <collision>
      <origin
        xyz="0 0 0"
        rpy="0 0 0" />
      <geometry>
        <mesh
          filename="package://wheelchair/meshes/Frame.STL" />
      </geometry>
    </collision>
  </link>
  <link
    name="Caster">
    <inertial>
      <origin
        xyz="-0.018675 -0.0023779 -0.066791"
        rpy="0 0 0" />
      <mass
        value="0.18692" />
      <inertia
        ixx="0.00031039"
        ixy="1.0543E-06"
        ixz="-0.00010185"
        iyy="0.00030225"
        iyz="-1.2968E-05"
        izz="0.00012277" />
    </inertial>
    <visual>
      <origin
        xyz="0 0 0"
        rpy="0 0 0" />
      <geometry>
        <mesh
          filename="package://wheelchair/meshes/Caster.STL" />
      </geometry>
      <material
        name="">
        <color
          rgba="0.89804 0.91765 0.92941 1" />
      </material>
    </visual>
    <collision>
      <origin
        xyz="0 0 0"
        rpy="0 0 0" />
      <geometry>
        <mesh
          filename="package://wheelchair/meshes/Caster.STL" />
      </geometry>
    </collision>
  </link>
  <joint
    name="Caster_cont"
    type="continuous">
    <origin
      xyz="0.5078 0 0.00635"
      rpy="0 0 0" />
    <parent
      link="Frame" />
    <child
      link="Caster" />
    <axis
      xyz="0 0 1" />
    <limit
      effort="0"
      velocity="20" />
  </joint>
  <link
    name="WheelF">
    <inertial>
      <origin
        xyz="0 0 -2.7756E-17"
        rpy="0 0 0" />
      <mass
        value="2.1315" />
      <inertia
        ixx="0.0052886"
        ixy="-3.2526E-19"
        ixz="-1.09E-21"
        iyy="0.010349"
        iyz="-3.0141E-20"
        izz="0.0052886" />
    </inertial>
    <visual>
      <origin
        xyz="0 0 0"
        rpy="0 0 0" />
      <geometry>
        <mesh
          filename="package://wheelchair/meshes/WheelF.STL" />
      </geometry>
      <material
        name="">
        <color
          rgba="0.89804 0.91765 0.92941 1" />
      </material>
    </visual>
    <collision>
      <origin
        xyz="0 0 0"
        rpy="0 0 0" />
      <geometry>
        <mesh
          filename="package://wheelchair/meshes/WheelF.STL" />
      </geometry>
    </collision>
  </link>
  <joint
    name="WheelF_cont"
    type="continuous">
    <origin
      xyz="-0.0518843000619276 -0.00660668610975347 -0.1478026"
      rpy="0 0 0.0" />
    <parent
      link="Caster" />
    <child
      link="WheelF" />
    <axis
      xyz="0 -1 0" />
    <limit
      effort="0"
      velocity="20" />
  </joint>
  <link
    name="SwingR">
    <inertial>
      <origin
        xyz="-0.14883 0.054597 -0.033745"
        rpy="0 0 0" />
      <mass
        value="4.8363" />
      <inertia
        ixx="0.0094524"
        ixy="-0.00067415"
        ixz="-0.0056619"
        iyy="0.022613"
        iyz="3.9175E-05"
        izz="0.018459" />
    </inertial>
    <visual>
      <origin
        xyz="0 0 0"
        rpy="0 0 0" />
      <geometry>
        <mesh
          filename="package://wheelchair/meshes/SwingR.STL" />
      </geometry>
      <material
        name="">
        <color
          rgba="0.75294 0.75294 0.75294 1" />
      </material>
    </visual>
    <collision>
      <origin
        xyz="0 0 0"
        rpy="0 0 0" />
      <geometry>
        <mesh
          filename="package://wheelchair/meshes/SwingR.STL" />
      </geometry>
    </collision>
  </link>
  <joint
    name="SwingR_rev"
    type="revolute">
    <origin
      xyz="-0.106 -0.2118548 -0.0238887"
      rpy="0 0 0" />
    <parent
      link="Frame" />
    <child
      link="SwingR" />
    <axis
      xyz="0 1 0" />
    <limit
      lower="-0.51732"
      upper="0.15533"
      effort="0"
      velocity="2" />
    <dynamics damping="0.7" friction="0.0"/>
  </joint>
  <link
    name="WheelR">
    <inertial>
      <origin
        xyz="1.8579E-05 -0.0076777 -2.2937E-05"
        rpy="0 0 0" />
      <mass
        value="2.1893" />
      <inertia
        ixx="0.07871"
        ixy="3.2611E-07"
        ixz="-4.0455E-07"
        iyy="0.15702"
        iyz="-4.0261E-07"
        izz="0.07871" />
    </inertial>
    <visual>
      <origin
        xyz="0 0 0"
        rpy="0 0 0" />
      <geometry>
        <mesh
          filename="package://wheelchair/meshes/WheelR.STL" />
      </geometry>
      <material
        name="">
        <color
          rgba="0.75294 0.75294 0.75294 1" />
      </material>
    </visual>
    <collision>
      <origin
        xyz="0 0 0"
        rpy="0 0 0" />
      <geometry>
        <mesh
          filename="package://wheelchair/meshes/WheelR.STL" />
      </geometry>
    </collision>
  </link>
  <joint
    name="WheelR_cont"
    type="continuous">
    <origin
      xyz="-0.232195893808092 -0.0517862 -0.0361948462997351"
      rpy="0 0 0" />
    <parent
      link="SwingR" />
    <child
      link="WheelR" />
    <axis
      xyz="0 1 0" />
    <limit
      effort="0"
      velocity="16.25" />
  </joint>
  <link
    name="SwingL">
    <inertial>
      <origin
        xyz="-0.14883 -0.054597 -0.033745"
        rpy="0 0 0" />
      <mass
        value="4.8363" />
      <inertia
        ixx="0.0094524"
        ixy="0.00067415"
        ixz="-0.0056619"
        iyy="0.022613"
        iyz="-3.9175E-05"
        izz="0.018459" />
    </inertial>
    <visual>
      <origin
        xyz="0 0 0"
        rpy="0 0 0" />
      <geometry>
        <mesh
          filename="package://wheelchair/meshes/SwingL.STL" />
      </geometry>
      <material
        name="">
        <color
          rgba="0.75294 0.75294 0.75294 1" />
      </material>
    </visual>
    <collision>
      <origin
        xyz="0 0 0"
        rpy="0 0 0" />
      <geometry>
        <mesh
          filename="package://wheelchair/meshes/SwingL.STL" />
      </geometry>
    </collision>
  </link>
  <joint
    name="SwingL_rev"
    type="revolute">
    <origin
      xyz="-0.106 0.20947 -0.023889"
      rpy="0 0 0" />
    <parent
      link="Frame" />
    <child
      link="SwingL" />
    <axis
      xyz="0 1 0" />
    <limit
      lower="-0.51732"
      upper="0.15533"
      effort="0"
      velocity="2" />
    <dynamics damping="0.7" friction="0.0"/>
  </joint>
  <link
    name="WheelL">
    <inertial>
      <origin
        xyz="1.8579E-05 0.0076777 -2.2937E-05"
        rpy="0 0 0" />
      <mass
        value="2.1893" />
      <inertia
        ixx="0.07871"
        ixy="-3.2611E-07"
        ixz="-4.0455E-07"
        iyy="0.15702"
        iyz="4.0261E-07"
        izz="0.07871" />
    </inertial>
    <visual>
      <origin
        xyz="0 0 0"
        rpy="0 0 0" />
      <geometry>
        <mesh
          filename="package://wheelchair/meshes/WheelL.STL" />
      </geometry>
      <material
        name="">
        <color
          rgba="0.75294 0.75294 0.75294 1" />
      </material>
    </visual>
    <collision>
      <origin
        xyz="0 0 0"
        rpy="0 0 0" />
      <geometry>
        <mesh
          filename="package://wheelchair/meshes/WheelL.STL" />
      </geometry>
    </collision>
  </link>
  <joint
    name="WheelL_cont"
    type="continuous">
    <origin
      xyz="-0.2322 0.054167 -0.036195"
      rpy="0 0 0" />
    <parent
      link="SwingL" />
    <child
      link="WheelL" />
    <axis
      xyz="0 1 0" />
    <limit
      effort="0"
      velocity="16.25" />
  </joint>

  <gazebo>
    <plugin name="differential_drive_controller"
            filename="libgazebo_ros_diff_drive.so">
      <leftJoint>WheelL_cont</leftJoint>
      <rightJoint>WheelR_cont</rightJoint>
      <!-- Robot frame to calculate odometry from, defaults to `base_footprint` -->
      <wheelSeparation>0.52728</wheelSeparation>
      <wheelDiameter>0.635</wheelDiameter>
      <!-- Wheel acceleration, in rad/s^2, defaults to 0.0 rad/s^2 -->
      <wheelAcceleration>1.0</wheelAcceleration>

      <!-- Maximum torque which the wheels can produce, in Nm, defaults to 5 Nm -->
      <wheelTorque>20</wheelTorque>

      <!-- Topic to receive geometry_msgs/Twist message commands, defaults to `cmd_vel` -->
      <commandTopic>cmd_vel</commandTopic>

      <!-- Topic to publish nav_msgs/Odometry messages, defaults to `odom` -->
      <odometryTopic>odom</odometryTopic>

      <!-- Odometry frame, defaults to `odom` -->
      <odometryFrame>odom</odometryFrame>

      <!-- Robot frame to calculate odometry from, defaults to `base_footprint` -->
      <robotBaseFrame>Frame</robotBaseFrame>

      <!-- Odometry source, 0 for ENCODER, 1 for WORLD, defaults to WORLD -->
      <odometrySource>1</odometrySource>

      <!-- Set to true to publish transforms for the wheel links, defaults to false -->
      <publishWheelTF>false                                                                                                                                                                                                                               </publishWheelTF>

      <!-- Set to true to publish transforms for the odometry, defaults to true -->
      <publishOdom>true</publishOdom>

      <!-- Set to true to publish sensor_msgs/JointState on /joint_states for the wheel joints, defaults to false -->
      <publishWheelJointState>true</publishWheelJointState>
    </plugin>
  </gazebo>

  <gazebo>
    <plugin name="joint_state_publisher"
    filename="libgazebo_ros_joint_state_publisher.so">
    <jointName>Caster_cont, WheelF_cont, SwingR_rev, SwingL_rev, WheelL_cont, WheelR_cont</jointName>
    </plugin>
  </gazebo>

  <transmission name="SwingL_trans">
    <type>transmission_interface/SimpleTransmission</type>
    <actuator name="SwingL_motor">
      <mechanicalReduction>1</mechanicalReduction>
    </actuator>
    <joint name="SwingL_rev">
      <hardwareInterface>EffortJointInterface</hardwareInterface>
    </joint>
  </transmission>  

  <transmission name="SwingR_trans">
    <type>transmission_interface/SimpleTransmission</type>
    <actuator name="SwingR_motor">
      <mechanicalReduction>1</mechanicalReduction>
    </actuator>
    <joint name="SwingR_rev">
      <hardwareInterface>EffortJointInterface</hardwareInterface>
    </joint>
  </transmission> 

  <gazebo>
    <plugin name="gazebo_ros_control" filename="libgazebo_ros_control.so">
      <robotNamespace>/wheelchair</robotNamespace>
    </plugin>
  </gazebo>
</robot>